Workbook

Sheet 구역
A1: ID | B1: 표기명 | C1: 광역 | D1: 남북 | E1: 원명칭 | F1: 유형 | G1: 조선 8도 | H1: 인구(만명) | I1: 원자료 인구(명) | J1: 인구 기준 | K1: 해안 | L1: 인접 해역 | M1: 섬 구분 | N1: 시작 항구 | O1: 농장 | P1: 어장 | Q1: 공장 | R1: 은행 | S1: 정유(석유/턴) | T1: 탄광(석탄/턴) | U1: 자체발전(전기/턴) | V1: 발전원·발전소 소재 | W1: 특산물 | X1: 초기 산출(만원/턴) | Y1: 식량 생산/턴 | Z1: 식량 수지/턴 | AA1: 기본 세수/턴 | AB1: 비고
A2: S001 | B2: 서울 송파구 | C2: 서울 | D2: 남 | E2: 서울특별시 송파구 | F2: 구·구역 | G2: 경기 | H2: 64.9 | I2: 649212 | J2: 2026.8 주민등록 | K2: N | O2: 0 | P2: 0 | Q2: 0 | R2: 2 | S2: 0 | T2: 0 | U2: 0 | X2: =설정!$B$4*H2+설정!$B$5*O2*(1+설정!$B$9*(O2-1))+설정!$B$6*P2*(1+설정!$B$9*(P2-1))+설정!$B$7*Q2*(1+설정!$B$9*(Q2-1))+설정!$B$8*R2*(1+설정!$B$9*(R2-1)) -> 3387 | Y2: =설정!$B$10*(O2*(1+설정!$B$9*(O2-1))+P2*(1+설정!$B$9*(P2-1))) -> 0 | Z2: =Y2-H2 -> -64.9 | AA2: =X2*설정!$B$11 -> 338.7
A3: S002 | B3: 서울 강남구 | C3: 서울 | D3: 남 | E3: 서울특별시 강남구 | F3: 구·구역 | G3: 경기 | H3: 55.2 | I3: 552357 | J3: 2026.8 주민등록 | K3: N | O3: 0 | P3: 0 | Q3: 0 | R3: 2 | S3: 0 | T3: 0 | U3: 0 | X3: =설정!$B$4*H3+설정!$B$5*O3*(1+설정!$B$9*(O3-1))+설정!$B$6*P3*(1+설정!$B$9*(P3-1))+설정!$B$7*Q3*(1+설정!$B$9*(Q3-1))+설정!$B$8*R3*(1+설정!$B$9*(R3-1)) -> 3096 | Y3: =설정!$B$10*(O3*(1+설정!$B$9*(O3-1))+P3*(1+설정!$B$9*(P3-1))) -> 0 | Z3: =Y3-H3 -> -55.2 | AA3: =X3*설정!$B$11 -> 309.6
A4: S003 | B4: 서울 강서구 | C4: 서울 | D4: 남 | E4: 서울특별시 강서구 | F4: 구·구역 | G4: 경기 | H4: 54.8 | I4: 547821 | J4: 2026.8 주민등록 | K4: N | O4: 0 | P4: 0 | Q4: 0 | R4: 1 | S4: 0 | T4: 0 | U4: 0 | X4: =설정!$B$4*H4+설정!$B$5*O4*(1+설정!$B$9*(O4-1))+설정!$B$6*P4*(1+설정!$B$9*(P4-1))+설정!$B$7*Q4*(1+설정!$B$9*(Q4-1))+설정!$B$8*R4*(1+설정!$B$9*(R4-1)) -> 2244 | Y4: =설정!$B$10*(O4*(1+설정!$B$9*(O4-1))+P4*(1+설정!$B$9*(P4-1))) -> 0 | Z4: =Y4-H4 -> -54.8 | AA4: =X4*설정!$B$11 -> 224.4
A5: S004 | B5: 서울 강동구 | C5: 서울 | D5: 남 | E5: 서울특별시 강동구 | F5: 구·구역 | G5: 경기 | H5: 49.8 | I5: 498222 | J5: 2026.8 주민등록 | K5: N | O5: 0 | P5: 0 | Q5: 0 | R5: 1 | S5: 0 | T5: 0 | U5: 0 | X5: =설정!$B$4*H5+설정!$B$5*O5*(1+설정!$B$9*(O5-1))+설정!$B$6*P5*(1+설정!$B$9*(P5-1))+설정!$B$7*Q5*(1+설정!$B$9*(Q5-1))+설정!$B$8*R5*(1+설정!$B$9*(R5-1)) -> 2094 | Y5: =설정!$B$10*(O5*(1+설정!$B$9*(O5-1))+P5*(1+설정!$B$9*(P5-1))) -> 0 | Z5: =Y5-H5 -> -49.8 | AA5: =X5*설정!$B$11 -> 209.4
A6: S005 | B6: 서울 노원구 | C6: 서울 | D6: 남 | E6: 서울특별시 노원구 | F6: 구·구역 | G6: 경기 | H6: 48 | I6: 480045 | J6: 2026.8 주민등록 | K6: N | O6: 0 | P6: 0 | Q6: 0 | R6: 1 | S6: 0 | T6: 0 | U6: 0 | X6: =설정!$B$4*H6+설정!$B$5*O6*(1+설정!$B$9*(O6-1))+설정!$B$6*P6*(1+설정!$B$9*(P6-1))+설정!$B$7*Q6*(1+설정!$B$9*(Q6-1))+설정!$B$8*R6*(1+설정!$B$9*(R6-1)) -> 2040 | Y6: =설정!$B$10*(O6*(1+설정!$B$9*(O6-1))+P6*(1+설정!$B$9*(P6-1))) -> 0 | Z6: =Y6-H6 -> -48 | AA6: =X6*설정!$B$11 -> 204
A7: S006 | B7: 서울 관악구 | C7: 서울 | D7: 남 | E7: 서울특별시 관악구 | F7: 구·구역 | G7: 경기 | H7: 47.7 | I7: 477297 | J7: 2026.8 주민등록 | K7: N | O7: 0 | P7: 0 | Q7: 0 | R7: 1 | S7: 0 | T7: 0 | U7: 0 | X7: =설정!$B$4*H7+설정!$B$5*O7*(1+설정!$B$9*(O7-1))+설정!$B$6*P7*(1+설정!$B$9*(P7-1))+설정!$B$7*Q7*(1+설정!$B$9*(Q7-1))+설정!$B$8*R7*(1+설정!$B$9*(R7-1)) -> 2031 | Y7: =설정!$B$10*(O7*(1+설정!$B$9*(O7-1))+P7*(1+설정!$B$9*(P7-1))) -> 0 | Z7: =Y7-H7 -> -47.7 | AA7: =X7*설정!$B$11 -> 203.1
A8: S007 | B8: 서울 은평구 | C8: 서울 | D8: 남 | E8: 서울특별시 은평구 | F8: 구·구역 | G8: 경기 | H8: 45.3 | I8: 452626 | J8: 2026.8 주민등록 | K8: N | O8: 0 | P8: 0 | Q8: 0 | R8: 1 | S8: 0 | T8: 0 | U8: 0 | X8: =설정!$B$4*H8+설정!$B$5*O8*(1+설정!$B$9*(O8-1))+설정!$B$6*P8*(1+설정!$B$9*(P8-1))+설정!$B$7*Q8*(1+설정!$B$9*(Q8-1))+설정!$B$8*R8*(1+설정!$B$9*(R8-1)) -> 1959 | Y8: =설정!$B$10*(O8*(1+설정!$B$9*(O8-1))+P8*(1+설정!$B$9*(P8-1))) -> 0 | Z8: =Y8-H8 -> -45.3 | AA8: =X8*설정!$B$11 -> 195.9
A9: S008 | B9: 서울 성북구 | C9: 서울 | D9: 남 | E9: 서울특별시 성북구 | F9: 구·구역 | G9: 경기 | H9: 42.1 | I9: 421106 | J9: 2026.8 주민등록 | K9: N | O9: 0 | P9: 0 | Q9: 0 | R9: 1 | S9: 0 | T9: 0 | U9: 0 | X9: =설정!$B$4*H9+설정!$B$5*O9*(1+설정!$B$9*(O9-1))+설정!$B$6*P9*(1+설정!$B$9*(P9-1))+설정!$B$7*Q9*(1+설정!$B$9*(Q9-1))+설정!$B$8*R9*(1+설정!$B$9*(R9-1)) -> 1863 | Y9: =설정!$B$10*(O9*(1+설정!$B$9*(O9-1))+P9*(1+설정!$B$9*(P9-1))) -> 0 | Z9: =Y9-H9 -> -42.1 | AA9: =X9*설정!$B$11 -> 186.3
A10: S009 | B10: 서울 양천구 | C10: 서울 | D10: 남 | E10: 서울특별시 양천구 | F10: 구·구역 | G10: 경기 | H10: 42 | I10: 420127 | J10: 2026.8 주민등록 | K10: N | O10: 0 | P10: 0 | Q10: 0 | R10: 1 | S10: 0 | T10: 0 | U10: 0 | X10: =설정!$B$4*H10+설정!$B$5*O10*(1+설정!$B$9*(O10-1))+설정!$B$6*P10*(1+설정!$B$9*(P10-1))+설정!$B$7*Q10*(1+설정!$B$9*(Q10-1))+설정!$B$8*R10*(1+설정!$B$9*(R10-1)) -> 1860 | Y10: =설정!$B$10*(O10*(1+설정!$B$9*(O10-1))+P10*(1+설정!$B$9*(P10-1))) -> 0 | Z10: =Y10-H10 -> -42 | AA10: =X10*설정!$B$11 -> 186
A11: S010 | B11: 서울 서초구 | C11: 서울 | D11: 남 | E11: 서울특별시 서초구 | F11: 구·구역 | G11: 경기 | H11: 41.7 | I11: 416928 | J11: 2026.8 주민등록 | K11: N | O11: 0 | P11: 0 | Q11: 0 | R11: 2 | S11: 0 | T11: 0 | U11: 0 | X11: =설정!$B$4*H11+설정!$B$5*O11*(1+설정!$B$9*(O11-1))+설정!$B$6*P11*(1+설정!$B$9*(P11-1))+설정!$B$7*Q11*(1+설정!$B$9*(Q11-1))+설정!$B$8*R11*(1+설정!$B$9*(R11-1)) -> 2691 | Y11: =설정!$B$10*(O11*(1+설정!$B$9*(O11-1))+P11*(1+설정!$B$9*(P11-1))) -> 0 | Z11: =Y11-H11 -> -41.7 | AA11: =X11*설정!$B$11 -> 269.1
A12: S011 | B12: 서울 구로구 | C12: 서울 | D12: 남 | E12: 서울특별시 구로구 | F12: 구·구역 | G12: 경기 | H12: 38.2 | I12: 382302 | J12: 2026.8 주민등록 | K12: N | O12: 0 | P12: 0 | Q12: 1 | R12: 1 | S12: 0 | T12: 0 | U12: 0 | X12: =설정!$B$4*H12+설정!$B$5*O12*(1+설정!$B$9*(O12-1))+설정!$B$6*P12*(1+설정!$B$9*(P12-1))+설정!$B$7*Q12*(1+설정!$B$9*(Q12-1))+설정!$B$8*R12*(1+설정!$B$9*(R12-1)) -> 2746 | Y12: =설정!$B$10*(O12*(1+설정!$B$9*(O12-1))+P12*(1+설정!$B$9*(P12-1))) -> 0 | Z12: =Y12-H12 -> -38.2 | AA12: =X12*설정!$B$11 -> 274.6
A13: S012 | B13: 서울 중랑구 | C13: 서울 | D13: 남 | E13: 서울특별시 중랑구 | F13: 구·구역 | G13: 경기 | H13: 37.7 | I13: 376504 | J13: 2026.8 주민등록 | K13: N | O13: 0 | P13: 0 | Q13: 0 | R13: 1 | S13: 0 | T13: 0 | U13: 0 | X13: =설정!$B$4*H13+설정!$B$5*O13*(1+설정!$B$9*(O13-1))+설정!$B$6*P13*(1+설정!$B$9*(P13-1))+설정!$B$7*Q13*(1+설정!$B$9*(Q13-1))+설정!$B$8*R13*(1+설정!$B$9*(R13-1)) -> 1731 | Y13: =설정!$B$10*(O13*(1+설정!$B$9*(O13-1))+P13*(1+설정!$B$9*(P13-1))) -> 0 | Z13: =Y13-H13 -> -37.7 | AA13: =X13*설정!$B$11 -> 173.1
... A26: S025 | B26: 서울 중구 | C26: 서울 | D26: 남 | E26: 서울특별시 중구 | F26: 구·구역 | G26: 경기 | H26: 11.7 | I26: 117305 | J26: 2026.8 주민등록 | K26: N | O26: 0 | P26: 0 | Q26: 0 | R26: 2 | S26: 0 | T26: 0 | U26: 0 | X26: =설정!$B$4*H26+설정!$B$5*O26*(1+설정!$B$9*(O26-1))+설정!$B$6*P26*(1+설정!$B$9*(P26-1))+설정!$B$7*Q26*(1+설정!$B$9*(Q26-1))+설정!$B$8*R26*(1+설정!$B$9*(R26-1)) -> 1791 | Y26: =설정!$B$10*(O26*(1+설정!$B$9*(O26-1))+P26*(1+설정!$B$9*(P26-1))) -> 0 | Z26: =Y26-H26 -> -11.7 | AA26: =X26*설정!$B$11 -> 179.1
A27: S026 | B27: 부산 해운대구 | C27: 부산 | D27: 남 | E27: 부산광역시 해운대구 | F27: 구·구역 | G27: 경상 | H27: 37 | I27: 369727 | J27: 2026.8 주민등록 | K27: Y | L27: 남동해 | O27: 0 | P27: 1 | Q27: 0 | R27: 2 | S27: 0 | T27: 0 | U27: 0 | X27: =설정!$B$4*H27+설정!$B$5*O27*(1+설정!$B$9*(O27-1))+설정!$B$6*P27*(1+설정!$B$9*(P27-1))+설정!$B$7*Q27*(1+설정!$B$9*(Q27-1))+설정!$B$8*R27*(1+설정!$B$9*(R27-1)) -> 2700 | Y27: =설정!$B$10*(O27*(1+설정!$B$9*(O27-1))+P27*(1+설정!$B$9*(P27-1))) -> 15 | Z27: =Y27-H27 -> -22 | AA27: =X27*설정!$B$11 -> 270
A28: S027 | B28: 부산 부산진구 | C28: 부산 | D28: 남 | E28: 부산광역시 부산진구 | F28: 구·구역 | G28: 경상 | H28: 36.4 | I28: 364184 | J28: 2026.8 주민등록 | K28: N | O28: 0 | P28: 0 | Q28: 0 | R28: 2 | S28: 0 | T28: 0 | U28: 0 | X28: =설정!$B$4*H28+설정!$B$5*O28*(1+설정!$B$9*(O28-1))+설정!$B$6*P28*(1+설정!$B$9*(P28-1))+설정!$B$7*Q28*(1+설정!$B$9*(Q28-1))+설정!$B$8*R28*(1+설정!$B$9*(R28-1)) -> 2532 | Y28: =설정!$B$10*(O28*(1+설정!$B$9*(O28-1))+P28*(1+설정!$B$9*(P28-1))) -> 0 | Z28: =Y28-H28 -> -36.4 | AA28: =X28*설정!$B$11 -> 253.2
A29: S028 | B29: 부산 사하구 | C29: 부산 | D29: 남 | E29: 부산광역시 사하구 | F29: 구·구역 | G29: 경상 | H29: 28.1 | I29: 281184 | J29: 2026.8 주민등록 | K29: Y | L29: 남동해 | O29: 0 | P29: 1 | Q29: 1 | R29: 1 | S29: 0 | T29: 0 | U29: 0 | X29: =설정!$B$4*H29+설정!$B$5*O29*(1+설정!$B$9*(O29-1))+설정!$B$6*P29*(1+설정!$B$9*(P29-1))+설정!$B$7*Q29*(1+설정!$B$9*(Q29-1))+설정!$B$8*R29*(1+설정!$B$9*(R29-1)) -> 2593 | Y29: =설정!$B$10*(O29*(1+설정!$B$9*(O29-1))+P29*(1+설정!$B$9*(P29-1))) -> 15 | Z29: =Y29-H29 -> -13.1 | AA29: =X29*설정!$B$11 -> 259.3
A30: S029 | B30: 부산 동래구 | C30: 부산 | D30: 남 | E30: 부산광역시 동래구 | F30: 구·구역 | G30: 경상 | H30: 27.1 | I30: 270512 | J30: 2026.8 주민등록 | K30: N | O30: 0 | P30: 0 | Q30: 0 | R30: 1 | S30: 0 | T30: 0 | U30: 0 | X30: =설정!$B$4*H30+설정!$B$5*O30*(1+설정!$B$9*(O30-1))+설정!$B$6*P30*(1+설정!$B$9*(P30-1))+설정!$B$7*Q30*(1+설정!$B$9*(Q30-1))+설정!$B$8*R30*(1+설정!$B$9*(R30-1)) -> 1413 | Y30: =설정!$B$10*(O30*(1+설정!$B$9*(O30-1))+P30*(1+설정!$B$9*(P30-1))) -> 0 | Z30: =Y30-H30 -> -27.1 | AA30: =X30*설정!$B$11 -> 141.3
A31: S030 | B31: 부산 북구 | C31: 부산 | D31: 남 | E31: 부산광역시 북구 | F31: 구·구역 | G31: 경상 | H31: 26 | I31: 260069 | J31: 2026.8 주민등록 | K31: N | O31: 0 | P31: 0 | Q31: 0 | R31: 1 | S31: 0 | T31: 0 | U31: 0 | X31: =설정!$B$4*H31+설정!$B$5*O31*(1+설정!$B$9*(O31-1))+설정!$B$6*P31*(1+설정!$B$9*(P31-1))+설정!$B$7*Q31*(1+설정!$B$9*(Q31-1))+설정!$B$8*R31*(1+설정!$B$9*(R31-1)) -> 1380 | Y31: =설정!$B$10*(O31*(1+설정!$B$9*(O31-1))+P31*(1+설정!$B$9*(P31-1))) -> 0 | Z31: =Y31-H31 -> -26 | AA31: =X31*설정!$B$11 -> 138
A32: S031 | B32: 부산 남구 | C32: 부산 | D32: 남 | E32: 부산광역시 남구 | F32: 구·구역 | G32: 경상 | H32: 25.5 | I32: 254960 | J32: 2026.8 주민등록 | K32: Y | L32: 남동해 | O32: 0 | P32: 1 | Q32: 0 | R32: 1 | S32: 0 | T32: 0 | U32: 0 | X32: =설정!$B$4*H32+설정!$B$5*O32*(1+설정!$B$9*(O32-1))+설정!$B$6*P32*(1+설정!$B$9*(P32-1))+설정!$B$7*Q32*(1+설정!$B$9*(Q32-1))+설정!$B$8*R32*(1+설정!$B$9*(R32-1)) -> 1515 | Y32: =설정!$B$10*(O32*(1+설정!$B$9*(O32-1))+P32*(1+설정!$B$9*(P32-1))) -> 15 | Z32: =Y32-H32 -> -10.5 | AA32: =X32*설정!$B$11 -> 151.5
A33: S032 | B33: 부산 연제구 | C33: 부산 | D33: 남 | E33: 부산광역시 연제구 | F33: 구·구역 | G33: 경상 | H33: 21.2 | I33: 211603 | J33: 2026.8 주민등록 | K33: N | O33: 0 | P33: 0 | Q33: 0 | R33: 1 | S33: 0 | T33: 0 | U33: 0 | X33: =설정!$B$4*H33+설정!$B$5*O33*(1+설정!$B$9*(O33-1))+설정!$B$6*P33*(1+설정!$B$9*(P33-1))+설정!$B$7*Q33*(1+설정!$B$9*(Q33-1))+설정!$B$8*R33*(1+설정!$B$9*(R33-1)) -> 1236 | Y33: =설정!$B$10*(O33*(1+설정!$B$9*(O33-1))+P33*(1+설정!$B$9*(P33-1))) -> 0 | Z33: =Y33-H33 -> -21.2 | AA33: =X33*설정!$B$11 -> 123.6
A34: S033 | B34: 부산 금정구 | C34: 부산 | D34: 남 | E34: 부산광역시 금정구 | F34: 구·구역 | G34: 경상 | H34: 20.5 | I34: 205341 | J34: 2026.8 주민등록 | K34: N | O34: 0 | P34: 0 | Q34: 0 | R34: 1 | S34: 0 | T34: 0 | U34: 0 | X34: =설정!$B$4*H34+설정!$B$5*O34*(1+설정!$B$9*(O34-1))+설정!$B$6*P34*(1+설정!$B$9*(P34-1))+설정!$B$7*Q34*(1+설정!$B$9*(Q34-1))+설정!$B$8*R34*(1+설정!$B$9*(R34-1)) -> 1215 | Y34: =설정!$B$10*(O34*(1+설정!$B$9*(O34-1))+P34*(1+설정!$B$9*(P34-1))) -> 0 | Z34: =Y34-H34 -> -20.5 | AA34: =X34*설정!$B$11 -> 121.5
A35: S034 | B35: 부산 사상구 | C35: 부산 | D35: 남 | E35: 부산광역시 사상구 | F35: 구·구역 | G35: 경상 | H35: 19.2 | I35: 191912 | J35: 2026.8 주민등록 | K35: N | O35: 0 | P35: 0 | Q35: 1 | R35: 1 | S35: 0 | T35: 0 | U35: 0 | X35: =설정!$B$4*H35+설정!$B$5*O35*(1+설정!$B$9*(O35-1))+설정!$B$6*P35*(1+설정!$B$9*(P35-1))+설정!$B$7*Q35*(1+설정!$B$9*(Q35-1))+설정!$B$8*R35*(1+설정!$B$9*(R35-1)) -> 2176 | Y35: =설정!$B$10*(O35*(1+설정!$B$9*(O35-1))+P35*(1+설정!$B$9*(P35-1))) -> 0 | Z35: =Y35-H35 -> -19.2 | AA35: =X35*설정!$B$11 -> 217.6
A36: S035 | B36: 부산 기장군 | C36: 부산 | D36: 남 | E36: 부산광역시 기장군 | F36: 군 | G36: 경상 | H36: 17.5 | I36: 175482 | J36: 2026.8 주민등록 | K36: Y | L36: 남동해,동남해 | O36: 1 | P36: 2 | Q36: 1 | R36: 1 | S36: 0 | T36: 0 | U36: 3 | V36: 원자력(고리) | W36: 기장 멸치 | X36: =설정!$B$4*H36+설정!$B$5*O36*(1+설정!$B$9*(O36-1))+설정!$B$6*P36*(1+설정!$B$9*(P36-1))+설정!$B$7*Q36*(1+설정!$B$9*(Q36-1))+설정!$B$8*R36*(1+설정!$B$9*(R36-1)) -> 2635 | Y36: =설정!$B$10*(O36*(1+설정!$B$9*(O36-1))+P36*(1+설정!$B$9*(P36-1))) -> 51 | Z36: =Y36-H36 -> 33.5 | AA36: =X36*설정!$B$11 -> 263.5
A37: S036 | B37: 부산 수영구 | C37: 부산 | D37: 남 | E37: 부산광역시 수영구 | F37: 구·구역 | G37: 경상 | H37: 16.9 | I37: 169336 | J37: 2026.8 주민등록 | K37: Y | L37: 남동해 | O37: 0 | P37: 1 | Q37: 0 | R37: 1 | S37: 0 | T37: 0 | U37: 0 | X37: =설정!$B$4*H37+설정!$B$5*O37*(1+설정!$B$9*(O37-1))+설정!$B$6*P37*(1+설정!$B$9*(P37-1))+설정!$B$7*Q37*(1+설정!$B$9*(Q37-1))+설정!$B$8*R37*(1+설정!$B$9*(R37-1)) -> 1257 | Y37: =설정!$B$10*(O37*(1+설정!$B$9*(O37-1))+P37*(1+설정!$B$9*(P37-1))) -> 15 | Z37: =Y37-H37 -> -1.9 | AA37: =X37*설정!$B$11 -> 125.7
A38: S037 | B38: 부산 강서구 | C38: 부산 | D38: 남 | E38: 부산광역시 강서구 | F38: 구·구역 | G38: 경상 | H38: 15.5 | I38: 154782 | J38: 2026.8 주민등록 | K38: Y | L38: 남동해 | O38: 1 | P38: 1 | Q38: 2 | R38: 1 | S38: 0 | T38: 0 | U38: 0 | W38: 대저 토마토 | X38: =설정!$B$4*H38+설정!$B$5*O38*(1+설정!$B$9*(O38-1))+설정!$B$6*P38*(1+설정!$B$9*(P38-1))+설정!$B$7*Q38*(1+설정!$B$9*(Q38-1))+설정!$B$8*R38*(1+설정!$B$9*(R38-1)) -> 3765 | Y38: =설정!$B$10*(O38*(1+설정!$B$9*(O38-1))+P38*(1+설정!$B$9*(P38-1))) -> 30 | Z38: =Y38-H38 -> 14.5 | AA38: =X38*설정!$B$11 -> 376.5
A39: S038 | B39: 부산 서구 | C39: 부산 | D39: 남 | E39: 부산광역시 서구 | F39: 구·구역 | G39: 경상 | H39: 10.1 | I39: 100964 | J39: 2026.8 주민등록 | K39: Y | L39: 남동해 | O39: 0 | P39: 2 | Q39: 0 | R39: 1 | S39: 0 | T39: 0 | U39: 0 | W39: 공동어시장 고등어 | X39: =설정!$B$4*H39+설정!$B$5*O39*(1+설정!$B$9*(O39-1))+설정!$B$6*P39*(1+설정!$B$9*(P39-1))+설정!$B$7*Q39*(1+설정!$B$9*(Q39-1))+설정!$B$8*R39*(1+설정!$B$9*(R39-1)) -> 1263 | Y39: =설정!$B$10*(O39*(1+설정!$B$9*(O39-1))+P39*(1+설정!$B$9*(P39-1))) -> 36 | Z39: =Y39-H39 -> 25.9 | AA39: =X39*설정!$B$11 -> 126.3
A40: S039 | B40: 부산 영도구 | C40: 부산 | D40: 남 | E40: 부산광역시 영도구 | F40: 구·구역 | G40: 경상 | H40: 10 | I40: 100170 | J40: 2026.8 주민등록 | K40: Y | L40: 남동해 | M40: 연륙 섬 | O40: 0 | P40: 1 | Q40: 0 | R40: 1 | S40: 0 | T40: 0 | U40: 0 | X40: =설정!$B$4*H40+설정!$B$5*O40*(1+설정!$B$9*(O40-1))+설정!$B$6*P40*(1+설정!$B$9*(P40-1))+설정!$B$7*Q40*(1+설정!$B$9*(Q40-1))+설정!$B$8*R40*(1+설정!$B$9*(R40-1)) -> 1050 | Y40: =설정!$B$10*(O40*(1+설정!$B$9*(O40-1))+P40*(1+설정!$B$9*(P40-1))) -> 15 | Z40: =Y40-H40 -> 5 | AA40: =X40*설정!$B$11 -> 105
A41: S040 | B41: 부산 동구 | C41: 부산 | D41: 남 | E41: 부산광역시 동구 | F41: 구·구역 | G41: 경상 | H41: 8.3 | I41: 83115 | J41: 2026.8 주민등록 | K41: Y | L41: 남동해 | O41: 0 | P41: 1 | Q41: 0 | R41: 1 | S41: 0 | T41: 0 | U41: 0 | X41: =설정!$B$4*H41+설정!$B$5*O41*(1+설정!$B$9*(O41-1))+설정!$B$6*P41*(1+설정!$B$9*(P41-1))+설정!$B$7*Q41*(1+설정!$B$9*(Q41-1))+설정!$B$8*R41*(1+설정!$B$9*(R41-1)) -> 999 | Y41: =설정!$B$10*(O41*(1+설정!$B$9*(O41-1))+P41*(1+설정!$B$9*(P41-1))) -> 15 | Z41: =Y41-H41 -> 6.7 | AA41: =X41*설정!$B$11 -> 99.9
A42: S041 | B42: 부산 중구 | C42: 부산 | D42: 남 | E42: 부산광역시 중구 | F42: 구·구역 | G42: 경상 | H42: 3.6 | I42: 36126 | J42: 2026.8 주민등록 | K42: Y | L42: 남동해 | O42: 0 | P42: 1 | Q42: 0 | R42: 2 | S42: 0 | T42: 0 | U42: 0 | X42: =설정!$B$4*H42+설정!$B$5*O42*(1+설정!$B$9*(O42-1))+설정!$B$6*P42*(1+설정!$B$9*(P42-1))+설정!$B$7*Q42*(1+설정!$B$9*(Q42-1))+설정!$B$8*R42*(1+설정!$B$9*(R42-1)) -> 1698 | Y42: =설정!$B$10*(O42*(1+설정!$B$9*(O42-1))+P42*(1+설정!$B$9*(P42-1))) -> 15 | Z42: =Y42-H42 -> 11.4 | AA42: =X42*설정!$B$11 -> 169.8
A43: S042 | B43: 대구 달서구 | C43: 대구 | D43: 남 | E43: 대구광역시 달서구 | F43: 구·구역 | G43: 경상 | H43: 51.3 | I43: 512577 | J43: 2026.8 주민등록 | K43: N | O43: 0 | P43: 0 | Q43: 1 | R43: 1 | S43: 0 | T43: 0 | U43: 0 | X43: =설정!$B$4*H43+설정!$B$5*O43*(1+설정!$B$9*(O43-1))+설정!$B$6*P43*(1+설정!$B$9*(P43-1))+설정!$B$7*Q43*(1+설정!$B$9*(Q43-1))+설정!$B$8*R43*(1+설정!$B$9*(R43-1)) -> 3139 | Y43: =설정!$B$10*(O43*(1+설정!$B$9*(O43-1))+P43*(1+설정!$B$9*(P43-1))) -> 0 | Z43: =Y43-H43 -> -51.3 | AA43: =X43*설정!$B$11 -> 313.9
A44: S043 | B44: 대구 수성구 | C44: 대구 | D44: 남 | E44: 대구광역시 수성구 | F44: 구·구역 | G44: 경상 | H44: 40.8 | I44: 407570 | J44: 2026.8 주민등록 | K44: N | O44: 0 | P44: 0 | Q44: 0 | R44: 2 | S44: 0 | T44: 0 | U44: 0 | X44: =설정!$B$4*H44+설정!$B$5*O44*(1+설정!$B$9*(O44-1))+설정!$B$6*P44*(1+설정!$B$9*(P44-1))+설정!$B$7*Q44*(1+설정!$B$9*(Q44-1))+설정!$B$8*R44*(1+설정!$B$9*(R44-1)) -> 2664 | Y44: =설정!$B$10*(O44*(1+설정!$B$9*(O44-1))+P44*(1+설정!$B$9*(P44-1))) -> 0 | Z44: =Y44-H44 -> -40.8 | AA44: =X44*설정!$B$11 -> 266.4
A45: S044 | B45: 대구 북구 | C45: 대구 | D45: 남 | E45: 대구광역시 북구 | F45: 구·구역 | G45: 경상 | H45: 40.6 | I45: 406214 | J45: 2026.8 주민등록 | K45: N | O45: 0 | P45: 0 | Q45: 1 | R45: 1 | S45: 0 | T45: 0 | U45: 0 | X45: =설정!$B$4*H45+설정!$B$5*O45*(1+설정!$B$9*(O45-1))+설정!$B$6*P45*(1+설정!$B$9*(P45-1))+설정!$B$7*Q45*(1+설정!$B$9*(Q45-1))+설정!$B$8*R45*(1+설정!$B$9*(R45-1)) -> 2818 | Y45: =설정!$B$10*(O45*(1+설정!$B$9*(O45-1))+P45*(1+설정!$B$9*(P45-1))) -> 0 | Z45: =Y45-H45 -> -40.6 | AA45: =X45*설정!$B$11 -> 281.8
A46: S045 | B46: 대구 동구 | C46: 대구 | D46: 남 | E46: 대구광역시 동구 | F46: 구·구역 | G46: 경상 | H46: 33.9 | I46: 338699 | J46: 2026.8 주민등록 | K46: N | O46: 0 | P46: 0 | Q46: 0 | R46: 1 | S46: 0 | T46: 0 | U46: 0 | X46: =설정!$B$4*H46+설정!$B$5*O46*(1+설정!$B$9*(O46-1))+설정!$B$6*P46*(1+설정!$B$9*(P46-1))+설정!$B$7*Q46*(1+설정!$B$9*(Q46-1))+설정!$B$8*R46*(1+설정!$B$9*(R46-1)) -> 1617 | Y46: =설정!$B$10*(O46*(1+설정!$B$9*(O46-1))+P46*(1+설정!$B$9*(P46-1))) -> 0 | Z46: =Y46-H46 -> -33.9 | AA46: =X46*설정!$B$11 -> 161.7
A47: S046 | B47: 대구 달성군 | C47: 대구 | D47: 남 | E47: 대구광역시 달성군 | F47: 군 | G47: 경상 | H47: 25.2 | I47: 251789 | J47: 2026.8 주민등록 | K47: N | O47: 1 | P47: 0 | Q47: 2 | R47: 1 | S47: 0 | T47: 0 | U47: 0 | X47: =설정!$B$4*H47+설정!$B$5*O47*(1+설정!$B$9*(O47-1))+설정!$B$6*P47*(1+설정!$B$9*(P47-1))+설정!$B$7*Q47*(1+설정!$B$9*(Q47-1))+설정!$B$8*R47*(1+설정!$B$9*(R47-1)) -> 3906 | Y47: =설정!$B$10*(O47*(1+설정!$B$9*(O47-1))+P47*(1+설정!$B$9*(P47-1))) -> 15 | Z47: =Y47-H47 -> -10.2 | AA47: =X47*설정!$B$11 -> 390.6
A48: S047 | B48: 대구 서구 | C48: 대구 | D48: 남 | E48: 대구광역시 서구 | F48: 구·구역 | G48: 경상 | H48: 16.3 | I48: 163319 | J48: 2026.8 주민등록 | K48: N | O48: 0 | P48: 0 | Q48: 1 | R48: 1 | S48: 0 | T48: 0 | U48: 0 | X48: =설정!$B$4*H48+설정!$B$5*O48*(1+설정!$B$9*(O48-1))+설정!$B$6*P48*(1+설정!$B$9*(P48-1))+설정!$B$7*Q48*(1+설정!$B$9*(Q48-1))+설정!$B$8*R48*(1+설정!$B$9*(R48-1)) -> 2089 | Y48: =설정!$B$10*(O48*(1+설정!$B$9*(O48-1))+P48*(1+설정!$B$9*(P48-1))) -> 0 | Z48: =Y48-H48 -> -16.3 | AA48: =X48*설정!$B$11 -> 208.9
A49: S048 | B49: 대구 남구 | C49: 대구 | D49: 남 | E49: 대구광역시 남구 | F49: 구·구역 | G49: 경상 | H49: 14.2 | I49: 141722 | J49: 2026.8 주민등록 | K49: N | O49: 0 | P49: 0 | Q49: 0 | R49: 1 | S49: 0 | T49: 0 | U49: 0 | X49: =설정!$B$4*H49+설정!$B$5*O49*(1+설정!$B$9*(O49-1))+설정!$B$6*P49*(1+설정!$B$9*(P49-1))+설정!$B$7*Q49*(1+설정!$B$9*(Q49-1))+설정!$B$8*R49*(1+설정!$B$9*(R49-1)) -> 1026 | Y49: =설정!$B$10*(O49*(1+설정!$B$9*(O49-1))+P49*(1+설정!$B$9*(P49-1))) -> 0 | Z49: =Y49-H49 -> -14.2 | AA49: =X49*설정!$B$11 -> 102.6
A50: S049 | B50: 대구 중구 | C50: 대구 | D50: 남 | E50: 대구광역시 중구 | F50: 구·구역 | G50: 경상 | H50: 10.2 | I50: 101894 | J50: 2026.8 주민등록 | K50: N | O50: 0 | P50: 0 | Q50: 0 | R50: 2 | S50: 0 | T50: 0 | U50: 0 | X50: =설정!$B$4*H50+설정!$B$5*O50*(1+설정!$B$9*(O50-1))+설정!$B$6*P50*(1+설정!$B$9*(P50-1))+설정!$B$7*Q50*(1+설정!$B$9*(Q50-1))+설정!$B$8*R50*(1+설정!$B$9*(R50-1)) -> 1746 | Y50: =설정!$B$10*(O50*(1+설정!$B$9*(O50-1))+P50*(1+설정!$B$9*(P50-1))) -> 0 | Z50: =Y50-H50 -> -10.2 | AA50: =X50*설정!$B$11 -> 174.6
A51: S050 | B51: 대구 군위군 | C51: 대구 | D51: 남 | E51: 대구광역시 군위군 | F51: 군 | G51: 경상 | H51: 2.2 | I51: 22493 | J51: 2026.8 주민등록 | K51: N | O51: 2 | P51: 0 | Q51: 1 | R51: 0 | S51: 0 | T51: 0 | U51: 0 | X51: =설정!$B$4*H51+설정!$B$5*O51*(1+설정!$B$9*(O51-1))+설정!$B$6*P51*(1+설정!$B$9*(P51-1))+설정!$B$7*Q51*(1+설정!$B$9*(Q51-1))+설정!$B$8*R51*(1+설정!$B$9*(R51-1)) -> 1426 | Y51: =설정!$B$10*(O51*(1+설정!$B$9*(O51-1))+P51*(1+설정!$B$9*(P51-1))) -> 36 | Z51: =Y51-H51 -> 33.8 | AA51: =X51*설정!$B$11 -> 142.6
A52: S051 | B52: 인천 부평구 | C52: 인천 | D52: 남 | E52: 인천광역시 부평구 | F52: 구·구역 | G52: 경기 | H52: 48.7 | I52: 487282 | J52: 2026.8 주민등록 | K52: N | O52: 0 | P52: 0 | Q52: 1 | R52: 1 | S52: 0 | T52: 0 | U52: 0 | X52: =설정!$B$4*H52+설정!$B$5*O52*(1+설정!$B$9*(O52-1))+설정!$B$6*P52*(1+설정!$B$9*(P52-1))+설정!$B$7*Q52*(1+설정!$B$9*(Q52-1))+설정!$B$8*R52*(1+설정!$B$9*(R52-1)) -> 3061 | Y52: =설정!$B$10*(O52*(1+설정!$B$9*(O52-1))+P52*(1+설정!$B$9*(P52-1))) -> 0 | Z52: =Y52-H52 -> -48.7 | AA52: =X52*설정!$B$11 -> 306.1
...

Sheet 설정
A1: 게임 상수 (노란 칸을 바꾸면 구역 시트의 산출·식량·세수 열이 다시 계산됩니다)
A3: 항목 | B3: 값
A4: 인구 산출 계수 (만원 / 인구 1만 명) | B4: 30
A5: 농장 기준 산출 | B5: 150
A6: 어장 기준 산출 | B6: 150
A7: 공장 기준 산출 (연료 배수 1.0 기준) | B7: 1000
A8: 은행 기준 산출 | B8: 600
A9: 단계 증가율 r (g(L)=L×(1+r×(L−1))) | B9: 0.2
A10: 식량 계수 (식량/턴 per g(L)) | B10: 15
A11: 기본 세율 | B11: 0.1
A12: 북한 인구 보정 배수 | B12: 1.5
A13: 인구 최대 성장률 G_MAX (/턴) | B13: 0.0025
A14: 랜드마크 건설비 (만원/턴) | B14: 100000
A15: 랜드마크 건설 턴 | B15: 15
... A17: 해안선 점유 시 해전 방어 보너스 | B17: 0.25
A18: 랜드마크 총비용 | B18: =B14*B15 -> 1500000
A20: 출처: 기획서 4·5·6절 기본값. 게임 코드의 config와 같은 값으로 유지합니다.

Sheet 광역요약
A1: 광역 | B1: 구분 | C1: 지역 수 | D1: 인구 합(만명) | E1: 농장 단계 합 | F1: 어장 단계 합 | G1: 공장 단계 합 | H1: 은행 단계 합 | I1: 초기 산출 합(만원/턴) | J1: 식량 수지 합/턴 | K1: 특산물 보유 지역
A2: 서울 | B2: 남 | C2: =COUNTIFS(구역!$C$2:$C$425,A2,구역!$D$2:$D$425,B2) -> 25 | D2: =SUMIFS(구역!$H$2:$H$425,구역!$C$2:$C$425,A2,구역!$D$2:$D$425,B2) -> 927.9 | E2: =SUMIFS(구역!$O$2:$O$425,구역!$C$2:$C$425,A2,구역!$D$2:$D$425,B2) -> 0 | F2: =SUMIFS(구역!$P$2:$P$425,구역!$C$2:$C$425,A2,구역!$D$2:$D$425,B2) -> 0 | G2: =SUMIFS(구역!$Q$2:$Q$425,구역!$C$2:$C$425,A2,구역!$D$2:$D$425,B2) -> 4 | H2: =SUMIFS(구역!$R$2:$R$425,구역!$C$2:$C$425,A2,구역!$D$2:$D$425,B2) -> 32 | I2: =SUMIFS(구역!$X$2:$X$425,구역!$C$2:$C$425,A2,구역!$D$2:$D$425,B2) -> 52717 | J2: =SUMIFS(구역!$Z$2:$Z$425,구역!$C$2:$C$425,A2,구역!$D$2:$D$425,B2) -> -927.9 | K2: =COUNTIFS(구역!$C$2:$C$425,A2,구역!$D$2:$D$425,B2,구역!$W$2:$W$425,"?*") -> 0
A3: 부산 | B3: 남 | C3: =COUNTIFS(구역!$C$2:$C$425,A3,구역!$D$2:$D$425,B3) -> 16 | D3: =SUMIFS(구역!$H$2:$H$425,구역!$C$2:$C$425,A3,구역!$D$2:$D$425,B3) -> 322.9 | E3: =SUMIFS(구역!$O$2:$O$425,구역!$C$2:$C$425,A3,구역!$D$2:$D$425,B3) -> 2 | F3: =SUMIFS(구역!$P$2:$P$425,구역!$C$2:$C$425,A3,구역!$D$2:$D$425,B3) -> 12 | G3: =SUMIFS(구역!$Q$2:$Q$425,구역!$C$2:$C$425,A3,구역!$D$2:$D$425,B3) -> 5 | H3: =SUMIFS(구역!$R$2:$R$425,구역!$C$2:$C$425,A3,구역!$D$2:$D$425,B3) -> 19 | I3: =SUMIFS(구역!$X$2:$X$425,구역!$C$2:$C$425,A3,구역!$D$2:$D$425,B3) -> 29427 | J3: =SUMIFS(구역!$Z$2:$Z$425,구역!$C$2:$C$425,A3,구역!$D$2:$D$425,B3) -> -100.9 | K3: =COUNTIFS(구역!$C$2:$C$425,A3,구역!$D$2:$D$425,B3,구역!$W$2:$W$425,"?*") -> 3
A4: 대구 | B4: 남 | C4: =COUNTIFS(구역!$C$2:$C$425,A4,구역!$D$2:$D$425,B4) -> 9 | D4: =SUMIFS(구역!$H$2:$H$425,구역!$C$2:$C$425,A4,구역!$D$2:$D$425,B4) -> 234.7 | E4: =SUMIFS(구역!$O$2:$O$425,구역!$C$2:$C$425,A4,구역!$D$2:$D$425,B4) -> 3 | F4: =SUMIFS(구역!$P$2:$P$425,구역!$C$2:$C$425,A4,구역!$D$2:$D$425,B4) -> 0 | G4: =SUMIFS(구역!$Q$2:$Q$425,구역!$C$2:$C$425,A4,구역!$D$2:$D$425,B4) -> 6 | H4: =SUMIFS(구역!$R$2:$R$425,구역!$C$2:$C$425,A4,구역!$D$2:$D$425,B4) -> 10 | I4: =SUMIFS(구역!$X$2:$X$425,구역!$C$2:$C$425,A4,구역!$D$2:$D$425,B4) -> 20431 | J4: =SUMIFS(구역!$Z$2:$Z$425,구역!$C$2:$C$425,A4,구역!$D$2:$D$425,B4) -> -183.7 | K4: =COUNTIFS(구역!$C$2:$C$425,A4,구역!$D$2:$D$425,B4,구역!$W$2:$W$425,"?*") -> 0
A5: 인천 | B5: 남 | C5: =COUNTIFS(구역!$C$2:$C$425,A5,구역!$D$2:$D$425,B5) -> 10 | D5: =SUMIFS(구역!$H$2:$H$425,구역!$C$2:$C$425,A5,구역!$D$2:$D$425,B5) -> 304.7 | E5: =SUMIFS(구역!$O$2:$O$425,구역!$C$2:$C$425,A5,구역!$D$2:$D$425,B5) -> 2 | F5: =SUMIFS(구역!$P$2:$P$425,구역!$C$2:$C$425,A5,구역!$D$2:$D$425,B5) -> 7 | G5: =SUMIFS(구역!$Q$2:$Q$425,구역!$C$2:$C$425,A5,구역!$D$2:$D$425,B5) -> 8 | H5: =SUMIFS(구역!$R$2:$R$425,구역!$C$2:$C$425,A5,구역!$D$2:$D$425,B5) -> 10 | I5: =SUMIFS(구역!$X$2:$X$425,구역!$C$2:$C$425,A5,구역!$D$2:$D$425,B5) -> 25591 | J5: =SUMIFS(구역!$Z$2:$Z$425,구역!$C$2:$C$425,A5,구역!$D$2:$D$425,B5) -> -163.7 | K5: =COUNTIFS(구역!$C$2:$C$425,A5,구역!$D$2:$D$425,B5,구역!$W$2:$W$425,"?*") -> 1
A6: 광주 | B6: 남 | C6: =COUNTIFS(구역!$C$2:$C$425,A6,구역!$D$2:$D$425,B6) -> 5 | D6: =SUMIFS(구역!$H$2:$H$425,구역!$C$2:$C$425,A6,구역!$D$2:$D$425,B6) -> 138.4 | E6: =SUMIFS(구역!$O$2:$O$425,구역!$C$2:$C$425,A6,구역!$D$2:$D$425,B6) -> 1 | F6: =SUMIFS(구역!$P$2:$P$425,구역!$C$2:$C$425,A6,구역!$D$2:$D$425,B6) -> 0 | G6: =SUMIFS(구역!$Q$2:$Q$425,구역!$C$2:$C$425,A6,구역!$D$2:$D$425,B6) -> 3 | H6: =SUMIFS(구역!$R$2:$R$425,구역!$C$2:$C$425,A6,구역!$D$2:$D$425,B6) -> 6 | I6: =SUMIFS(구역!$X$2:$X$425,구역!$C$2:$C$425,A6,구역!$D$2:$D$425,B6) -> 11542 | J6: =SUMIFS(구역!$Z$2:$Z$425,구역!$C$2:$C$425,A6,구역!$D$2:$D$425,B6) -> -123.4 | K6: =COUNTIFS(구역!$C$2:$C$425,A6,구역!$D$2:$D$425,B6,구역!$W$2:$W$425,"?*") -> 0
A7: 대전 | B7: 남 | C7: =COUNTIFS(구역!$C$2:$C$425,A7,구역!$D$2:$D$425,B7) -> 5 | D7: =SUMIFS(구역!$H$2:$H$425,구역!$C$2:$C$425,A7,구역!$D$2:$D$425,B7) -> 144.3 | E7: =SUMIFS(구역!$O$2:$O$425,구역!$C$2:$C$425,A7,구역!$D$2:$D$425,B7) -> 0 | F7: =SUMIFS(구역!$P$2:$P$425,구역!$C$2:$C$425,A7,구역!$D$2:$D$425,B7) -> 0 | G7: =SUMIFS(구역!$Q$2:$Q$425,구역!$C$2:$C$425,A7,구역!$D$2:$D$425,B7) -> 3 | H7: =SUMIFS(구역!$R$2:$R$425,구역!$C$2:$C$425,A7,구역!$D$2:$D$425,B7) -> 7 | I7: =SUMIFS(구역!$X$2:$X$425,구역!$C$2:$C$425,A7,구역!$D$2:$D$425,B7) -> 12409 | J7: =SUMIFS(구역!$Z$2:$Z$425,구역!$C$2:$C$425,A7,구역!$D$2:$D$425,B7) -> -144.3 | K7: =COUNTIFS(구역!$C$2:$C$425,A7,구역!$D$2:$D$425,B7,구역!$W$2:$W$425,"?*") -> 0
A8: 울산 | B8: 남 | C8: =COUNTIFS(구역!$C$2:$C$425,A8,구역!$D$2:$D$425,B8) -> 5 | D8: =SUMIFS(구역!$H$2:$H$425,구역!$C$2:$C$425,A8,구역!$D$2:$D$425,B8) -> 108.6 | E8: =SUMIFS(구역!$O$2:$O$425,구역!$C$2:$C$425,A8,구역!$D$2:$D$425,B8) -> 1 | F8: =SUMIFS(구역!$P$2:$P$425,구역!$C$2:$C$425,A8,구역!$D$2:$D$425,B8) -> 3 | G8: =SUMIFS(구역!$Q$2:$Q$425,구역!$C$2:$C$425,A8,구역!$D$2:$D$425,B8) -> 9 | H8: =SUMIFS(구역!$R$2:$R$425,구역!$C$2:$C$425,A8,구역!$D$2:$D$425,B8) -> 6 | I8: =SUMIFS(구역!$X$2:$X$425,구역!$C$2:$C$425,A8,구역!$D$2:$D$425,B8) -> 18298 | J8: =SUMIFS(구역!$Z$2:$Z$425,구역!$C$2:$C$425,A8,구역!$D$2:$D$425,B8) -> -48.6 | K8: =COUNTIFS(구역!$C$2:$C$425,A8,구역!$D$2:$D$425,B8,구역!$W$2:$W$425,"?*") -> 1
A9: 세종 | B9: 남 | C9: =COUNTIFS(구역!$C$2:$C$425,A9,구역!$D$2:$D$425,B9) -> 1 | D9: =SUMIFS(구역!$H$2:$H$425,구역!$C$2:$C$425,A9,구역!$D$2:$D$425,B9) -> 39.1 | E9: =SUMIFS(구역!$O$2:$O$425,구역!$C$2:$C$425,A9,구역!$D$2:$D$425,B9) -> 1 | F9: =SUMIFS(구역!$P$2:$P$425,구역!$C$2:$C$425,A9,구역!$D$2:$D$425,B9) -> 0 | G9: =SUMIFS(구역!$Q$2:$Q$425,구역!$C$2:$C$425,A9,구역!$D$2:$D$425,B9) -> 1 | H9: =SUMIFS(구역!$R$2:$R$425,구역!$C$2:$C$425,A9,구역!$D$2:$D$425,B9) -> 2 | I9: =SUMIFS(구역!$X$2:$X$425,구역!$C$2:$C$425,A9,구역!$D$2:$D$425,B9) -> 3763 | J9: =SUMIFS(구역!$Z$2:$Z$425,구역!$C$2:$C$425,A9,구역!$D$2:$D$425,B9) -> -24.1 | K9: =COUNTIFS(구역!$C$2:$C$425,A9,구역!$D$2:$D$425,B9,구역!$W$2:$W$425,"?*") -> 1
A10: 경기 | B10: 남 | C10: =COUNTIFS(구역!$C$2:$C$425,A10,구역!$D$2:$D$425,B10) -> 31 | D10: =SUMIFS(구역!$H$2:$H$425,구역!$C$2:$C$425,A10,구역!$D$2:$D$425,B10) -> 1377.2 | E10: =SUMIFS(구역!$O$2:$O$425,구역!$C$2:$C$425,A10,구역!$D$2:$D$425,B10) -> 21 | F10: =SUMIFS(구역!$P$2:$P$425,구역!$C$2:$C$425,A10,구역!$D$2:$D$425,B10) -> 3 | G10: =SUMIFS(구역!$Q$2:$Q$425,구역!$C$2:$C$425,A10,구역!$D$2:$D$425,B10) -> 36 | H10: =SUMIFS(구역!$R$2:$R$425,구역!$C$2:$C$425,A10,구역!$D$2:$D$425,B10) -> 33 | I10: =SUMIFS(구역!$X$2:$X$425,구역!$C$2:$C$425,A10,구역!$D$2:$D$425,B10) -> 105356 | J10: =SUMIFS(구역!$Z$2:$Z$425,구역!$C$2:$C$425,A10,구역!$D$2:$D$425,B10) -> -993.2 | K10: =COUNTIFS(구역!$C$2:$C$425,A10,구역!$D$2:$D$425,B10,구역!$W$2:$W$425,"?*") -> 11
A11: 강원 | B11: 남 | C11: =COUNTIFS(구역!$C$2:$C$425,A11,구역!$D$2:$D$425,B11) -> 16 | D11: =SUMIFS(구역!$H$2:$H$425,구역!$C$2:$C$425,A11,구역!$D$2:$D$425,B11) -> 144 | E11: =SUMIFS(구역!$O$2:$O$425,구역!$C$2:$C$425,A11,구역!$D$2:$D$425,B11) -> 14 | F11: =SUMIFS(구역!$P$2:$P$425,구역!$C$2:$C$425,A11,구역!$D$2:$D$425,B11) -> 6 | G11: =SUMIFS(구역!$Q$2:$Q$425,구역!$C$2:$C$425,A11,구역!$D$2:$D$425,B11) -> 5 | H11: =SUMIFS(구역!$R$2:$R$425,구역!$C$2:$C$425,A11,구역!$D$2:$D$425,B11) -> 7 | I11: =SUMIFS(구역!$X$2:$X$425,구역!$C$2:$C$425,A11,구역!$D$2:$D$425,B11) -> 16640 | J11: =SUMIFS(구역!$Z$2:$Z$425,구역!$C$2:$C$425,A11,구역!$D$2:$D$425,B11) -> 168 | K11: =COUNTIFS(구역!$C$2:$C$425,A11,구역!$D$2:$D$425,B11,구역!$W$2:$W$425,"?*") -> 15
A12: 강원 | B12: 남북 병합 | C12: =COUNTIFS(구역!$C$2:$C$425,A12,구역!$D$2:$D$425,B12) -> 2 | D12: =SUMIFS(구역!$H$2:$H$425,구역!$C$2:$C$425,A12,구역!$D$2:$D$425,B12) -> 25.2 | E12: =SUMIFS(구역!$O$2:$O$425,구역!$C$2:$C$425,A12,구역!$D$2:$D$425,B12) -> 3 | F12: =SUMIFS(구역!$P$2:$P$425,구역!$C$2:$C$425,A12,구역!$D$2:$D$425,B12) -> 2 | G12: =SUMIFS(구역!$Q$2:$Q$425,구역!$C$2:$C$425,A12,구역!$D$2:$D$425,B12) -> 0 | H12: =SUMIFS(구역!$R$2:$R$425,구역!$C$2:$C$425,A12,구역!$D$2:$D$425,B12) -> 0 | I12: =SUMIFS(구역!$X$2:$X$425,구역!$C$2:$C$425,A12,구역!$D$2:$D$425,B12) -> 1626 | J12: =SUMIFS(구역!$Z$2:$Z$425,구역!$C$2:$C$425,A12,구역!$D$2:$D$425,B12) -> 61.8 | K12: =COUNTIFS(구역!$C$2:$C$425,A12,구역!$D$2:$D$425,B12,구역!$W$2:$W$425,"?*") -> 2
A13: 강원 | B13: 북 | C13: =COUNTIFS(구역!$C$2:$C$425,A13,구역!$D$2:$D$425,B13) -> 15 | D13: =SUMIFS(구역!$H$2:$H$425,구역!$C$2:$C$425,A13,구역!$D$2:$D$425,B13) -> 203.2 | E13: =SUMIFS(구역!$O$2:$O$425,구역!$C$2:$C$425,A13,구역!$D$2:$D$425,B13) -> 17 | F13: =SUMIFS(구역!$P$2:$P$425,구역!$C$2:$C$425,A13,구역!$D$2:$D$425,B13) -> 6 | G13: =SUMIFS(구역!$Q$2:$Q$425,구역!$C$2:$C$425,A13,구역!$D$2:$D$425,B13) -> 2 | H13: =SUMIFS(구역!$R$2:$R$425,구역!$C$2:$C$425,A13,구역!$D$2:$D$425,B13) -> 3 | I13: =SUMIFS(구역!$X$2:$X$425,구역!$C$2:$C$425,A13,구역!$D$2:$D$425,B13) -> 14166 | J13: =SUMIFS(구역!$Z$2:$Z$425,구역!$C$2:$C$425,A13,구역!$D$2:$D$425,B13) -> 159.8 | K13: =COUNTIFS(구역!$C$2:$C$425,A13,구역!$D$2:$D$425,B13,구역!$W$2:$W$425,"?*") -> 8
... A32: 양강 | B32: 북 | C32: =COUNTIFS(구역!$C$2:$C$425,A32,구역!$D$2:$D$425,B32) -> 12 | D32: =SUMIFS(구역!$H$2:$H$425,구역!$C$2:$C$425,A32,구역!$D$2:$D$425,B32) -> 107.9 | E32: =SUMIFS(구역!$O$2:$O$425,구역!$C$2:$C$425,A32,구역!$D$2:$D$425,B32) -> 13 | F32: =SUMIFS(구역!$P$2:$P$425,구역!$C$2:$C$425,A32,구역!$D$2:$D$425,B32) -> 0 | G32: =SUMIFS(구역!$Q$2:$Q$425,구역!$C$2:$C$425,A32,구역!$D$2:$D$425,B32) -> 2 | H32: =SUMIFS(구역!$R$2:$R$425,구역!$C$2:$C$425,A32,구역!$D$2:$D$425,B32) -> 2 | I32: =SUMIFS(구역!$X$2:$X$425,구역!$C$2:$C$425,A32,구역!$D$2:$D$425,B32) -> 8447 | J32: =SUMIFS(구역!$Z$2:$Z$425,구역!$C$2:$C$425,A32,구역!$D$2:$D$425,B32) -> 93.1 | K32: =COUNTIFS(구역!$C$2:$C$425,A32,구역!$D$2:$D$425,B32,구역!$W$2:$W$425,"?*") -> 5
A33: 합계 | C33: =SUM(C2:C32) -> 424 | D33: =SUM(D2:D32) -> 8611.2 | E33: =SUM(E2:E32) -> 416 | F33: =SUM(F2:F32) -> 156 | G33: =SUM(G2:G32) -> 211 | H33: =SUM(H2:H32) -> 249 | I33: =SUM(I2:I32) -> 743016 | J33: =SUM(J2:J32) -> 784.8 | K33: =SUM(K2:K32) -> 195
A35: 남북 특산물 밀도
A36: 남 | B36: =COUNTIFS(구역!$D$2:$D$425,"남",구역!$W$2:$W$425,"?*")/COUNTIF(구역!$D$2:$D$425,"남") -> 0.52863436
A37: 북 | B37: =COUNTIFS(구역!$D$2:$D$425,"북",구역!$W$2:$W$425,"?*")/COUNTIF(구역!$D$2:$D$425,"북") -> 0.37113402
A38: 남:북 비율 | B38: =B36/B37 -> 1.4243759
A40: 식량 수지 합이 양수면 시작 시점 전국 식량이 소비보다 많다는 뜻입니다(목표: 소비의 약 1.1배).

Sheet 조선8도
A1: 조선 8도 | B1: 지역 수 | C1: 인구 합(만명) | D1: 초기 산출 합(만원/턴) | E1: 현재 광역 구성
A2: 경기 | B2: =COUNTIF(구역!$G$2:$G$425,A2) -> 68 | C2: =SUMIF(구역!$G$2:$G$425,A2,구역!$H$2:$H$425) -> 2666.5 | D2: =SUMIF(구역!$G$2:$G$425,A2,구역!$X$2:$X$425) -> 189505 | E2: 서울·인천·경기, 황북 개성·장풍
A3: 충청 | B3: =COUNTIF(구역!$G$2:$G$425,A3) -> 32 | C3: =SUMIF(구역!$G$2:$G$425,A3,구역!$H$2:$H$425) -> 557.6 | D3: =SUMIF(구역!$G$2:$G$425,A3,구역!$X$2:$X$425) -> 65428 | E3: 충북·충남·대전·세종
A4: 전라 | B4: =COUNTIF(구역!$G$2:$G$425,A4) -> 43 | C4: =SUMIF(구역!$G$2:$G$425,A4,구역!$H$2:$H$425) -> 554 | D4: =SUMIF(구역!$G$2:$G$425,A4,구역!$X$2:$X$425) -> 64490 | E4: 전북·전남·광주·제주
A5: 경상 | B5: =COUNTIF(구역!$G$2:$G$425,A5) -> 70 | C5: =SUMIF(구역!$G$2:$G$425,A5,구역!$H$2:$H$425) -> 1234.9 | D5: =SUMIF(구역!$G$2:$G$425,A5,구역!$X$2:$X$425) -> 134937 | E5: 경북·경남·부산·대구·울산
A6: 강원 | B6: =COUNTIF(구역!$G$2:$G$425,A6) -> 33 | C6: =SUMIF(구역!$G$2:$G$425,A6,구역!$H$2:$H$425) -> 372.4 | D6: =SUMIF(구역!$G$2:$G$425,A6,구역!$X$2:$X$425) -> 32432 | E6: 강원(남·북)
A7: 황해 | B7: =COUNTIF(구역!$G$2:$G$425,A7) -> 36 | C7: =SUMIF(구역!$G$2:$G$425,A7,구역!$H$2:$H$425) -> 608.7 | D7: =SUMIF(구역!$G$2:$G$425,A7,구역!$X$2:$X$425) -> 39501 | E7: 황북(개성·장풍·중화·상원·승호 제외)·황남
A8: 평안 | B8: =COUNTIF(구역!$G$2:$G$425,A8) -> 93 | C8: =SUMIF(구역!$G$2:$G$425,A8,구역!$H$2:$H$425) -> 1700.1 | D8: =SUMIF(구역!$G$2:$G$425,A8,구역!$X$2:$X$425) -> 146353 | E8: 평양·남포·평북·평남·자강, 황북 중화·상원·승호
A9: 함경 | B9: =COUNTIF(구역!$G$2:$G$425,A9) -> 49 | C9: =SUMIF(구역!$G$2:$G$425,A9,구역!$H$2:$H$425) -> 917 | D9: =SUMIF(구역!$G$2:$G$425,A9,구역!$X$2:$X$425) -> 70370 | E9: 함남·함북·양강·라선
A11: 랜드마크승리: 8도 모두에 랜드마크를 짓고, 그중 하나는 자국 수도 구역이어야 합니다.

Sheet 해역
A1: ID | B1: 해역 | C1: 범위 | D1: 인접 해역 | E1: 인접 육지 타일 수 | F1: 해안선 점유 조건
A2: SEA1 | B2: 서북해 | C2: NLL 북쪽 서해 | D2: 서남해 | E2: =COUNTIF(구역!$L$2:$L$425,"*"&B2&"*") -> 33 | F2: 이 해역에 닿는 육지 타일을 모두 보유 → 어장 +25%, 이 해역 해전 방어 +25%
A3: SEA2 | B3: 서남해 | C3: NLL 남쪽 서해 (인천~전남 신안) | D3: 서북해, 남서해 | E3: =COUNTIF(구역!$L$2:$L$425,"*"&B3&"*") -> 32 | F3: 이 해역에 닿는 육지 타일을 모두 보유 → 어장 +25%, 이 해역 해전 방어 +25%
A4: SEA3 | B4: 남서해 | C4: 진도~광양 | D4: 서남해, 남동해 | E4: =COUNTIF(구역!$L$2:$L$425,"*"&B4&"*") -> 13 | F4: 이 해역에 닿는 육지 타일을 모두 보유 → 어장 +25%, 이 해역 해전 방어 +25%
A5: SEA4 | B5: 남동해 | C5: 하동~부산 | D5: 남서해, 동남해 | E5: =COUNTIF(구역!$L$2:$L$425,"*"&B5&"*") -> 19 | F5: 이 해역에 닿는 육지 타일을 모두 보유 → 어장 +25%, 이 해역 해전 방어 +25%
A6: SEA5 | B6: 동남해 | C6: 강원 고성 남쪽 동해 | D6: 남동해, 동북해 | E6: =COUNTIF(구역!$L$2:$L$425,"*"&B6&"*") -> 16 | F6: 이 해역에 닿는 육지 타일을 모두 보유 → 어장 +25%, 이 해역 해전 방어 +25%
A7: SEA6 | B7: 동북해 | C7: 강원 고성 북쪽 동해 | D7: 동남해 | E7: =COUNTIF(구역!$L$2:$L$425,"*"&B7&"*") -> 24 | F7: 이 해역에 닿는 육지 타일을 모두 보유 → 어장 +25%, 이 해역 해전 방어 +25%

Sheet 인접 예외
A1: 구역 A | B1: 구역 B | C1: 연결 수단 | D1: 규칙
A2: 인천 영종구 | B2: 인천 서해구 | C2: 영종대교 | D2: 육상 인접으로 취급(보병·전차 이동·돌격 가능)
A3: 인천 영종구 | B3: 인천 연수구 | C3: 인천대교 | D3: 육상 인접으로 취급(보병·전차 이동·돌격 가능)
A4: 인천 강화군 | B4: 경기 김포시 | C4: 강화대교·초지대교 | D4: 육상 인접으로 취급(보병·전차 이동·돌격 가능)
A5: 경남 거제시 | B5: 부산 강서구 | C5: 거가대교 | D5: 육상 인접으로 취급(보병·전차 이동·돌격 가능)
A6: 경남 거제시 | B6: 경남 통영시 | C6: 거제대교·신거제대교 | D6: 육상 인접으로 취급(보병·전차 이동·돌격 가능)
A7: 경남 남해군 | B7: 경남 하동군 | C7: 남해대교·노량대교 | D7: 육상 인접으로 취급(보병·전차 이동·돌격 가능)
A8: 경남 남해군 | B8: 경남 사천시 | C8: 창선·삼천포대교 | D8: 육상 인접으로 취급(보병·전차 이동·돌격 가능)
A9: 전남 진도군 | B9: 전남 해남군 | C9: 진도대교 | D9: 육상 인접으로 취급(보병·전차 이동·돌격 가능)
A10: 전남 완도군 | B10: 전남 해남군 | C10: 완도대교 | D10: 육상 인접으로 취급(보병·전차 이동·돌격 가능)
A11: 전남 신안군 | B11: 전남 목포시 | C11: 압해대교 | D11: 육상 인접으로 취급(보병·전차 이동·돌격 가능)
A12: 전남 신안군 | B12: 전남 무안군 | C12: 김대중대교 | D12: 육상 인접으로 취급(보병·전차 이동·돌격 가능)
... A18: 평북 신도군 | B18: 평북 신의주시 | C18: 비단섬 제방(확인 필요) | D18: 육상 인접으로 취급(보병·전차 이동·돌격 가능)
A20: 무연륙 섬(울릉, 제주, 서귀포)은 해역을 통해서만 드나듭니다.

Sheet 설명
A1: 열 설명
A2: 인구(만명) | B2: 남한은 행정안전부 주민등록인구 2026년 8월 말(0.1만 단위). 북한은 2008 센서스 × 1.5. 강원 고성·철원, 황남 옹진(옛 인천 옹진 포함)은 남북 합산.
A3: 표기명 | B3: 광역 두 글자 + 공백 + 기초 이름과 시·군·구·구역 접미사. 세종은 "세종시".
A4: 조선 8도 | B4: 랜드마크승리 판정용 구분. 개성·장풍은 경기, 중화·상원·승호는 평안, 제주는 전라, 양강·라선은 함경.
A5: 섬 구분 / 시작 항구 | B5: 연륙 섬은 인접 예외 시트의 다리로 육지처럼 이동. 무연륙 섬은 항구를 기본 보유하고, 이곳에서 시작하는 세력은 상륙함 1척을 추가로 받음.
A6: 농장·어장·공장·은행 | B6: 시작 단계 0~2. 1차(농장·어장)·2차(공장)·3차(은행) 산업 비중 기반 분류. 어장은 해안 지역만 1 이상.
A7: 정유 / 탄광 / 자체발전 | B7: 시작 산출(턴당). 정유 7곳은 원안 지정, 탄광은 현존·과거 주요 탄전, 자체발전은 원전·대형 수력.
A8: 특산물 | B8: 남한은 지역 대표 농수산물. 북한은 알려진 특산물에 더해, 남북 밀도를 1.5:1 수준으로 맞추려고 지형·기후 기반 게임용 배정을 추가(비고 열 표시).
A9: 공식 열 | B9: 설정 시트 상수를 참조하는 수식. 설정 값을 바꾸면 자동 재계산.
A11: 출처
A12: 남한 인구 | B12: 행정안전부 주민등록인구통계 2026년 8월 말 기준 (나무위키 「기초자치단체 인구 순위」 2026-09-12 수정본 정리값, 합계 51,084,159명). https://namu.wiki/w/기초자치단체 인구 순위
A13: 북한 인구 | B13: DPR Korea Central Bureau of Statistics, 2008 Population Census National Report (2009), Table 2 — https://dprkorea.un.org/sites/default/files/2019-07/Census-2008.pdf. 라선은 원자료가 시 합계뿐이라 라진 60%·선봉 40%로 추정 분할.
A15: 행정구역 기준 | B15: 남한 2026년 9월: 인천 제물포·영종·서해·검단구, 대구 군위군 포함. 광주·전남은 전남광주통합특별시로 통합됐으나 표기 접두어는 광주·전남으로 유지(기획서 확인 사항). 북한: 2010년 평양 축소 이후, 남포특별시, 라선특별시(라진·선봉구역), 청진·함흥은 구역 합산.
